Workbook

Sheet Cover & Legend
B2: 3PL WAREHOUSING - MASTER CHARGE SCHEDULE
B5: ERP Quotation Master | Reviewed, Restructured & Extended | Kingdom of Saudi Arabia
B7: DOCUMENT CONTROL
B8: Document Title | C8: 3PL Warehousing Master Charge Schedule
B9: Purpose | C9: Charge master for ERP quotation module configuration
B10: Source Document | C10: warehousing_rates.xlsx (client supplied, 104 rows, single sheet)
B11: Currency | C11: SAR - Saudi Riyal
B12: VAT Rate (ZATCA) | C12: 0.15
B13: Quotation Validity | C13: 30 days from date of issue
B14: Standard Working Hours | C14: 08:00 - 17:00, Sunday to Thursday (8-hour shift)
B15: Weekend | C15: Friday & Saturday
B16: Storage Billing Cycle | C16: Two cycles per month: 1st-15th and 16th-month end
B17: Payment Terms | C17: 30 days net from invoice date (subject to credit approval)
B18: Total Charge Lines | C18: =COUNTA('Rate Card Master (ERP)'!$A$8:$A$310) -> 303
B20: RATE STATUS LEGEND
B21: Status | C21: Meaning | F21: Action Required
B22: C - Client Provided | C22: Rate taken from your uploaded file with no change to the value. | F22: None - verify it is still current.
B23: X - Corrected | C23: The line existed but the rate, description or logic was wrong or internally inconsistent. | F23: Read the matching note on the 'Review & Corrections' sheet, then approve.
B24: N - New - Confirm | C24: Charge head added during review. It did not exist in your file. | F24: Set your own commercial rate before go-live. Rates shown are market-indicative placeholders.
B26: COST HEAD STRUCTURE
B27: Cost Head | E27: Code Prefix | F27: Lines
B28: 01 - Storage | E28: STO | F28: =COUNTIF('Rate Card Master (ERP)'!$B$8:$B$310,$B28) -> 52
B29: 02 - Inbound Handling (Receiving) | E29: HIN | F29: =COUNTIF('Rate Card Master (ERP)'!$B$8:$B$310,$B29) -> 26
B30: 03 - Outbound Handling (Dispatch) | E30: HOT | F30: =COUNTIF('Rate Card Master (ERP)'!$B$8:$B$310,$B30) -> 30
B31: 04 - Cross Dock & Transfer | E31: XDK | F31: =COUNTIF('Rate Card Master (ERP)'!$B$8:$B$310,$B31) -> 15
B32: 05 - Value Added Services | E32: VAS | F32: =COUNTIF('Rate Card Master (ERP)'!$B$8:$B$310,$B32) -> 25
B33: 06 - Packing Materials & Consumables | E33: PKG | F33: =COUNTIF('Rate Card Master (ERP)'!$B$8:$B$310,$B33) -> 17
B34: 07 - Equipment Hire | E34: EQP | F34: =COUNTIF('Rate Card Master (ERP)'!$B$8:$B$310,$B34) -> 22
B35: 08 - Manpower | E35: MAN | F35: =COUNTIF('Rate Card Master (ERP)'!$B$8:$B$310,$B35) -> 30
B36: 09 - Inventory Management | E36: INV | F36: =COUNTIF('Rate Card Master (ERP)'!$B$8:$B$310,$B36) -> 10
B37: 10 - Documentation & Administration | E37: DOC | F37: =COUNTIF('Rate Card Master (ERP)'!$B$8:$B$310,$B37) -> 9
B38: 11 - Compliance, Licensing & Customs | E38: CMP | F38: =COUNTIF('Rate Card Master (ERP)'!$B$8:$B$310,$B38) -> 13
B39: 12 - Returns & Reverse Logistics | E39: RET | F39: =COUNTIF('Rate Card Master (ERP)'!$B$8:$B$310,$B39) -> 10
... B43: 16 - Ancillary, Surcharges & Penalties | E43: ANC | F43: =COUNTIF('Rate Card Master (ERP)'!$B$8:$B$310,$B43) -> 18
B45: NOTE ON PLACEHOLDER RATES: Every line marked 'N - New - Confirm' carries a market-indicative placeholder rate so the ERP can be loaded and tested end to end. These are NOT quoted prices. Replace each one with your own costed rate before the schedule is issued to any customer.

Sheet Rate Card Master (ERP)
A1: RATE CARD MASTER - ERP CHARGE CONFIGURATION
A2: All rates in SAR and exclusive of VAT unless the 'VAT Applicable' column reads 'No'. VAT and VAT-inclusive columns are live formulas driven by the VAT rate on the Cover sheet. Percentage-based lines (UOM containing '%') are stored as decimals - 0.25 renders as 25.0%.
A4: LOAD KEY: Column A = ERP charge code (unique). Column B = Level 1 cost head. Column C = Level 2 sub head. Column K = billing frequency driver. Column M = approval status.
A7: Charge Code | B7: Cost Head | C7: Sub Head | D7: Charge Description | E7: Cargo / Applicability | F7: UOM | G7: Rate (SAR) | H7: VAT (SAR) | I7: Rate incl. VAT (SAR) | J7: Min. Charge (SAR) | K7: Billing Type | L7: VAT Applicable | M7: Rate Status | N7: Remarks
A8: STO-001 | B8: 01 - Storage | C8: Ambient / Dry | D8: Storage - General Cargo (Ambient, Non-Temperature Controlled) | E8: General Cargo | F8: SQM / Month | G8: 45 | H8: =IF(AND($L8="Yes",ISERROR(SEARCH("%",$F8))),$G8*'Cover & Legend'!$C$12,0) -> 6.75 | I8: =IF(ISERROR(SEARCH("%",$F8)),$G8+$H8,0) -> 51.75 | J8: 2500 | K8: Recurring - Monthly | L8: Yes | M8: Client Provided | N8: Client rate. Floor-area basis. Requires Municipality / Civil Defense approval. Min. charge is per client per month.
A9: STO-002 | B9: 01 - Storage | C9: Ambient / Dry | D9: Storage - General Cargo (Ambient) | E9: General Cargo | F9: Pallet Position / Month | G9: 45 | H9: =IF(AND($L9="Yes",ISERROR(SEARCH("%",$F9))),$G9*'Cover & Legend'!$C$12,0) -> 6.75 | I9: =IF(ISERROR(SEARCH("%",$F9)),$G9+$H9,0) -> 51.75 | J9: 2500 | K9: Recurring - Monthly | L9: Yes | M9: Client Provided | N9: Client rate. Pallet position basis. See CORRECTION #1 - SQM and pallet rate should not be identical.
A10: STO-003 | B10: 01 - Storage | C10: Ambient / Dry | D10: Storage - General Cargo (Ambient) - Short Term | E10: General Cargo | F10: Pallet / Day | G10: 2 | H10: =IF(AND($L10="Yes",ISERROR(SEARCH("%",$F10))),$G10*'Cover & Legend'!$C$12,0) -> 0.3 | I10: =IF(ISERROR(SEARCH("%",$F10)),$G10+$H10,0) -> 2.3 | J10: 500 | K10: Per Day | L10: Yes | M10: Client Provided | N10: Client rate. Applies to stays under one full billing cycle. Implied uplift 33% over pro-rata monthly.
A11: STO-004 | B11: 01 - Storage | C11: Temperature Controlled | D11: Storage - Temperature Controlled (Non-Food, 18-25 C) | E11: General Cargo - AC | F11: SQM / Month | G11: 65 | H11: =IF(AND($L11="Yes",ISERROR(SEARCH("%",$F11))),$G11*'Cover & Legend'!$C$12,0) -> 9.75 | I11: =IF(ISERROR(SEARCH("%",$F11)),$G11+$H11,0) -> 74.75 | J11: 2500 | K11: Recurring - Monthly | L11: Yes | M11: Corrected | N11: CORRECTION #2 - temperature band was not stated in source file. Band fixed at 18-25 C. Municipality / Civil Defense approval required.
A12: STO-005 | B12: 01 - Storage | C12: Temperature Controlled | D12: Storage - Temperature Controlled (Non-Food, 18-25 C) | E12: General Cargo - AC | F12: Pallet Position / Month | G12: 65 | H12: =IF(AND($L12="Yes",ISERROR(SEARCH("%",$F12))),$G12*'Cover & Legend'!$C$12,0) -> 9.75 | I12: =IF(ISERROR(SEARCH("%",$F12)),$G12+$H12,0) -> 74.75 | J12: 2500 | K12: Recurring - Monthly | L12: Yes | M12: Client Provided | N12: Client rate.
A13: STO-006 | B13: 01 - Storage | C13: Temperature Controlled | D13: Storage - Temperature Controlled (Non-Food) - Short Term | E13: General Cargo - AC | F13: Pallet / Day | G13: 4 | H13: =IF(AND($L13="Yes",ISERROR(SEARCH("%",$F13))),$G13*'Cover & Legend'!$C$12,0) -> 0.6 | I13: =IF(ISERROR(SEARCH("%",$F13)),$G13+$H13,0) -> 4.6 | J13: 500 | K13: Per Day | L13: Yes | M13: Client Provided | N13: Client rate. Implied uplift 85% over pro-rata monthly - highest in the card. Review for consistency.
A14: STO-007 | B14: 01 - Storage | C14: Food Grade | D14: Storage - Food, Temperature Controlled (18-25 C) | E14: Food | F14: SQM / Month | G14: 75 | H14: =IF(AND($L14="Yes",ISERROR(SEARCH("%",$F14))),$G14*'Cover & Legend'!$C$12,0) -> 11.25 | I14: =IF(ISERROR(SEARCH("%",$F14)),$G14+$H14,0) -> 86.25 | J14: 3000 | K14: Recurring - Monthly | L14: Yes | M14: Client Provided | N14: Requires SFDA Food Storage Licence. Segregated food-grade zone, pest control programme mandatory.
A15: STO-008 | B15: 01 - Storage | C15: Food Grade | D15: Storage - Food, Temperature Controlled (18-25 C) | E15: Food | F15: Pallet Position / Month | G15: 75 | H15: =IF(AND($L15="Yes",ISERROR(SEARCH("%",$F15))),$G15*'Cover & Legend'!$C$12,0) -> 11.25 | I15: =IF(ISERROR(SEARCH("%",$F15)),$G15+$H15,0) -> 86.25 | J15: 3000 | K15: Recurring - Monthly | L15: Yes | M15: Client Provided | N15: Requires SFDA Food Storage Licence.
A16: STO-009 | B16: 01 - Storage | C16: Food Grade | D16: Storage - Food, Temperature Controlled - Short Term | E16: Food | F16: Pallet / Day | G16: 4 | H16: =IF(AND($L16="Yes",ISERROR(SEARCH("%",$F16))),$G16*'Cover & Legend'!$C$12,0) -> 0.6 | I16: =IF(ISERROR(SEARCH("%",$F16)),$G16+$H16,0) -> 4.6 | J16: 500 | K16: Per Day | L16: Yes | M16: Client Provided | N16: Client rate.
A17: STO-010 | B17: 01 - Storage | C17: Food Grade | D17: Storage - Food, Dry / Non-Temperature Controlled | E17: Food | F17: SQM / Month | G17: 65 | H17: =IF(AND($L17="Yes",ISERROR(SEARCH("%",$F17))),$G17*'Cover & Legend'!$C$12,0) -> 9.75 | I17: =IF(ISERROR(SEARCH("%",$F17)),$G17+$H17,0) -> 74.75 | J17: 3000 | K17: Recurring - Monthly | L17: Yes | M17: Client Provided | N17: Requires SFDA Food Storage Licence.
A18: STO-011 | B18: 01 - Storage | C18: Food Grade | D18: Storage - Food, Dry / Non-Temperature Controlled | E18: Food | F18: Pallet Position / Month | G18: 65 | H18: =IF(AND($L18="Yes",ISERROR(SEARCH("%",$F18))),$G18*'Cover & Legend'!$C$12,0) -> 9.75 | I18: =IF(ISERROR(SEARCH("%",$F18)),$G18+$H18,0) -> 74.75 | J18: 3000 | K18: Recurring - Monthly | L18: Yes | M18: Client Provided | N18: Requires SFDA Food Storage Licence.
A19: STO-012 | B19: 01 - Storage | C19: Food Grade | D19: Storage - Food, Dry - Short Term | E19: Food | F19: Pallet / Day | G19: 3.5 | H19: =IF(AND($L19="Yes",ISERROR(SEARCH("%",$F19))),$G19*'Cover & Legend'!$C$12,0) -> 0.525 | I19: =IF(ISERROR(SEARCH("%",$F19)),$G19+$H19,0) -> 4.025 | J19: 500 | K19: Per Day | L19: Yes | M19: Client Provided | N19: Client rate.
... A310: ANC-018 | B310: 16 - Ancillary, Surcharges & Penalties | C310: Commercial | D310: Annual Rate Escalation | E310: All | F310: % of Contract Value | G310: 0.05 | H310: =IF(AND($L310="Yes",ISERROR(SEARCH("%",$F310))),$G310*'Cover & Legend'!$C$12,0) -> 0 | I310: =IF(ISERROR(SEARCH("%",$F310)),$G310+$H310,0) -> 0 | J310: 0 | K310: Recurring - Annual | L310: No | M310: New - Confirm | N310: NEW - NOT A LINE CHARGE. Contractual escalation clause, applied at each anniversary. Include in T&C.
D312: TOTAL CHARGE LINES | G312: =COUNTA($A$8:$A$310) -> 303
D313: Client Provided (unchanged) | G313: =COUNTIF($M$8:$M$310,"Client Provided") -> 78
D314: Corrected | G314: =COUNTIF($M$8:$M$310,"Corrected") -> 22
D315: New - Confirm | G315: =COUNTIF($M$8:$M$310,"New - Confirm") -> 203

Sheet Storage Rate Matrix
A1: STORAGE RATE MATRIX BY CARGO CLASS
A2: Column E computes what the daily rate implies as a monthly equivalent (daily x 30) and column F shows the uplift over the stated monthly rate. A consistent card should show a similar uplift on every row - see Correction #2.
A4: Cargo Class | B4: Rate / SQM / Month | C4: Rate / Pallet Position / Month | D4: Rate / Pallet / Day | E4: Implied Monthly (Daily x 30) | F4: Uplift vs Monthly | G4: Approval / Licence Required | H4: Rate Status
A5: General Cargo (Ambient / Dry) | B5: 45 | C5: 45 | D5: 2 | E5: =$D5*30 -> 60 | F5: =IFERROR($E5/$C5-1,"") -> 0.33333333 | G5: Municipality / Civil Defense | H5: Client Provided
A6: Temperature Controlled, Non-Food (18-25 C) | B6: 65 | C6: 65 | D6: 4 | E6: =$D6*30 -> 120 | F6: =IFERROR($E6/$C6-1,"") -> 0.84615385 | G6: Municipality / Civil Defense | H6: Corrected
A7: Food - Temperature Controlled (18-25 C) | B7: 75 | C7: 75 | D7: 4 | E7: =$D7*30 -> 120 | F7: =IFERROR($E7/$C7-1,"") -> 0.6 | G7: SFDA Food Storage Licence | H7: Client Provided
A8: Food - Dry / Non-Temperature Controlled | B8: 65 | C8: 65 | D8: 3.5 | E8: =$D8*30 -> 105 | F8: =IFERROR($E8/$C8-1,"") -> 0.61538462 | G8: SFDA Food Storage Licence | H8: Client Provided
A9: Medical Devices (18-25 C) | B9: 95 | C9: 95 | D9: 5 | E9: =$D9*30 -> 150 | F9: =IFERROR($E9/$C9-1,"") -> 0.57894737 | G9: SFDA Medical Device Storage Licence | H9: Client Provided
A10: Cosmetics (18-25 C) | B10: 95 | C10: 95 | D10: 5 | E10: =$D10*30 -> 150 | F10: =IFERROR($E10/$C10-1,"") -> 0.57894737 | G10: SFDA Cosmetics Storage Licence | H10: Client Provided
A11: Animal Feed (18-25 C) | B11: 95 | C11: 95 | D11: 5 | E11: =$D11*30 -> 150 | F11: =IFERROR($E11/$C11-1,"") -> 0.57894737 | G11: SFDA Animal Feed Storage Licence | H11: Client Provided
A12: Dangerous Goods - Dry / Ambient | B12: 95 | C12: 95 | D12: 5 | E12: =$D12*30 -> 150 | F12: =IFERROR($E12/$C12-1,"") -> 0.57894737 | G12: MOI-Approved DG Warehouse | H12: Corrected
A13: Dangerous Goods - Temp. Controlled (18-25 C) | B13: 180 | C13: 180 | D13: 9 | E13: =$D13*30 -> 270 | F13: =IFERROR($E13/$C13-1,"") -> 0.5 | G13: MOI-Approved DG Warehouse | H13: Corrected
A14: General Chemicals (Non-DG), Ambient | B14: 65 | C14: 65 | D14: 3.5 | E14: =$D14*30 -> 105 | F14: =IFERROR($E14/$C14-1,"") -> 0.61538462 | G14: 3PL General Chemical Approved Warehouse | H14: Corrected
A15: Chilled Chamber (+2 to +8 C) | B15: 165 | C15: 165 | D15: 9 | E15: =$D15*30 -> 270 | F15: =IFERROR($E15/$C15-1,"") -> 0.63636364 | G15: SFDA Cold Store Licence | H15: New - Confirm
A16: Frozen Chamber (-18 to -25 C) | B16: 240 | C16: 240 | D16: 13 | E16: =$D16*30 -> 390 | F16: =IFERROR($E16/$C16-1,"") -> 0.625 | G16: SFDA Cold Store Licence | H16: New - Confirm
... A24: Mezzanine Level | B24: 30 | C24: 30 | D24: 1.8 | E24: =$D24*30 -> 54 | F24: =IFERROR($E24/$C24-1,"") -> 0.8 | G24: Municipality / Civil Defense | H24: New - Confirm
A26: STORAGE BILLING RULES
A27: Billing basis | B27: Storage is billed on the GREATER of actual floor area occupied (SQM) or allocated pallet positions. The basis must be fixed per client in the contract - not left to the operator to choose at invoice time.
A28: Standard pallet definition | B28: 1,200 x 1,000 mm footprint, maximum 1,200 mm stack height, maximum gross weight 1,000 kg. Anything exceeding any one of these three limits is charged as two pallet positions.
A29: Euro pallet | B29: 1,200 x 800 mm. Charged at 0.85 of a standard pallet position where a separate Euro tariff is not agreed.
A30: Billing cycle | B30: Two cycles per calendar month: 1st-15th and 16th-month end. A pallet present on any day of a cycle attracts the full cycle charge.
A31: Free storage period | B31: Nil by default. Storage accrues from the GRN date inclusive. Any free period must be a written contractual concession.
A32: Part month | B32: Charged per cycle as above, not pro-rata per day, unless the daily tariff has been specifically agreed.
A33: Daily tariff eligibility | B33: The daily rate applies only where total stay is under 15 days. Beyond 15 days the monthly tariff applies retrospectively from day one.
A34: Minimum charge | B34: SAR 2,500 per client per month for ambient classes; SAR 5,000 for SFDA-regulated; SAR 7,500 for DG and cold chain.
A35: Empty pallet storage | B35: Charged at 50% of the applicable cargo storage rate.
A36: Rate review | B36: Rates are fixed for 12 months from contract start, then subject to the annual escalation clause (ANC-018).

Sheet Review & Corrections
A1: REVIEW FINDINGS & CORRECTION LOG
A2: Every change made to your original file, with the reason. Nothing was altered silently.
A4: # | B4: Area | C4: What Your File Said | D4: What Was Done & Why | E4: Severity
A5: 1 | B5: Storage - billing basis | C5: The SQM rate and the pallet rate are identical on every row, under a header reading 'Standard Pallet/month equals to 1 Square meter'. | D5: Kept your rates but split them into separate ERP lines and added an explicit billing-basis rule. A standard 1.2 x 1.0 m pallet occupies 1.2 SQM of floor, and a racked pallet consumes far less floor per position than a floor-stacked one. Treating the two as equal under-recovers on racked storage and over-recovers on floor storage. Decide the basis per client and fix it in the contract. | E5: High
A6: 2 | B6: Storage - daily vs monthly | C6: Daily rates carry no consistent relationship to the monthly rates. General cargo implies a 33% uplift, temperature controlled implies 85%, medical 58%. | D6: Rates left as you set them, but the Storage Rate Matrix now computes the implied uplift on every row so the inconsistency is visible. Either normalise to a single short-stay uplift or be ready to justify the spread to a customer who compares rows. | E6: Medium
A7: 3 | B7: Storage - missing daily rates | C7: Three rows carry the text 'min. per month' in the daily rate column instead of a rate: DG temperature controlled, DG dry, and general chemicals. | D7: Rates inserted (SAR 9, SAR 5 and SAR 3.5 per pallet per day) using the same short-stay logic as the comparable classes. A text string in a numeric ERP field will fail import, so this had to be resolved either way. Confirm the values. | E7: High
A8: 4 | B8: Handling - weight bands overlap | C8: Piece handling bands read 'up to 15 kgs', 'up to 40 kgs', 'up to 60 kgs'. | D8: Re-cut as mutually exclusive ranges (up to 15 / 15.1-40 / 40.1-60). As written, a 30 kg piece satisfies two bands and the ERP cannot resolve which rate to apply. Added bands for 60.1-100 kg and over 100 kg, which your card had no rate for at all. | E8: High
A9: 5 | B9: Order processing | C9: 'Order processing charges charges (Mendatory) SAR 25/Order'. | D9: Typos corrected and the unit defined: one order equals one outbound release or delivery note regardless of line count. Added a separate per-line charge (HOT-002), because a flat per-order fee under-recovers badly on multi-SKU picks. | E9: Low
A10: 6 | B10: Handling - truck tier error | C10: 'Manual loading 4toner (Dyna) SAR 500/5Toner'. The description says 4 ton, the unit says 5 ton, and the matching offloading line is 5 ton. | D10: Corrected to 5 Ton throughout. There is no 4-ton tier anywhere else in the card, so this was a transcription error. | E10: Medium
A11: 7 | B11: Manpower - no standard supervisor rate | C11: Supervisor appears only under 'Overtime charges' at SAR 150/hour and SAR 750/day. There is no normal-hours supervisor rate anywhere. | D11: Created a standard supervisor tier (SAR 100/hour, SAR 700/day) and kept your SAR 150 as the overtime rate, which now sits correctly at 1.5x standard. Without a base rate you cannot bill a supervisor on a normal working day. | E11: High
A12: 8 | B12: Manpower - overtime at standard rate | C12: 'Overtime charges: Labor per hour SAR 50, Labor per day SAR 350' - identical to the standard labour rates listed directly above. | D12: Overtime labour raised to SAR 75/hour. Saudi Labour Law Article 107 requires overtime at 150% of the basic wage, so billing overtime at the standard rate means paying the premium out of your own margin on every overtime hour worked. | E12: High
A13: 9 | B13: Manpower - holiday rate inversion | C13: 'Local Holidays overtime charges: Labor per hour SAR 750, Labor per day SAR 450.' The hourly rate is higher than the full-day rate. | D13: Rebuilt the holiday tier on a consistent basis where the day rate equals seven times the hourly rate (SAR 100/hour, SAR 700/day). As written, a customer booking 8 hours would be quoted SAR 6,000 against a SAR 450 day rate. This is the single most commercially dangerous line in the file. | E13: Critical
A14: 10 | B14: Manpower - Eid rate inconsistency | C14: 'Eid/Government holidays: Labor per hour SAR 200, Labor per day SAR 700.' Eight hours at SAR 200 is SAR 1,600 against a SAR 700 day rate. Supervisor shows the same problem: SAR 350/hour against SAR 1,500/day. | D14: Rebuilt on the same seven-times-hourly basis used throughout. Labour SAR 150/hour and SAR 1,050/day; supervisor SAR 250/hour and SAR 1,750/day. Your supervisor day rate moved from SAR 1,500 to SAR 1,750 - confirm if you want to hold 1,500 instead. | E14: High
A15: 11 | B15: Inventory - undefined line | C15: 'Stock cycle SAR 5/Pallet' with no unit, frequency or description. | D15: Restated as a per-occurrence cycle count (INV-002) and separated from the recurring monthly inventory management charge (INV-001), which was the only other inventory line. Added full physical stock take, reconciliation reporting and SKU setup, none of which existed. | E15: Medium
A16: 12 | B16: Insurance - not a chargeable basis | C16: 'Insurance charges: 1% of cargo insurance.' | D16: Restated as 1% per annum of declared cargo value with a SAR 1,500 minimum premium. As written the line is circular - 1% of the insurance is not a calculable figure. Also added a liability cap line (INS-004), which matters more than the premium itself: without a stated cap your exposure on a damaged high-value pallet is unlimited. | E16: Critical
... A29: 25 | B29: No charge codes or cost head structure | C29: A single flat sheet of 104 rows with no codes, no grouping and no unit of measure column. | D29: Restructured into 16 cost heads with unique charge codes, explicit UOM, minimum charge, billing frequency and VAT flag on every line. This is the structure an ERP quotation module needs in order to import the master. | E29: High

Sheet Commercial Terms
A1: COMMERCIAL TERMS & CONDITIONS OF QUOTATION
A4: A. PRICING & TAX
B5: Currency | C5: All rates are quoted in Saudi Riyal (SAR).
B6: VAT | C6: All rates are exclusive of VAT. VAT is applied at the prevailing ZATCA rate, currently 15%, on all taxable supplies. Insurance premiums and late payment charges are handled separately per their own tax treatment.
B7: E-Invoicing | C7: All invoices are issued as ZATCA-compliant electronic invoices (Fatoora) with QR code and required Arabic fields.
B8: Validity | C8: This quotation is valid for 30 days from the date of issue. Rates are firm for 12 months from contract commencement.
B9: Escalation | C9: Rates are subject to an annual escalation of up to 5% at each contract anniversary, or the published CPI, whichever is lower.
B10: Exclusions | C10: Unless expressly listed as a charge line, the following are excluded: customs duty and government fees, third-party laboratory testing, shipping line demurrage and detention, product liability, and any service not described in this schedule.
A12: B. OPERATING HOURS
B13: Standard hours | C13: 08:00 to 17:00, Sunday to Thursday. One 8-hour shift including a one-hour break.
B14: Weekend | C14: Friday and Saturday. Facility closed unless prior arrangement is made; weekend opening charges apply.
B15: Overtime trigger | C15: Any labour performed beyond the 8-hour standard shift on a working day is charged at the overtime rate, in line with Saudi Labour Law Article 107.
B16: Public holidays | C16: Eid Al Fitr, Eid Al Adha, Saudi National Day, Founding Day and any other day declared by the authorities. Holiday tariffs apply.
B17: Dock appointments | C17: All inbound and outbound vehicles require a confirmed dock slot booked at least 24 hours in advance. Unbooked arrivals are subject to surcharge and to availability.
A19: C. MEASUREMENT & BILLING
B20: Chargeable weight | C20: Where a rate is weight-based, the greater of actual gross weight or volumetric weight applies. Volumetric conversion: 1 CBM = 167 kg.
B21: Rounding | C21: CBM is rounded up to two decimal places. Weight is rounded up to the next whole kilogram. Pallet positions are rounded up to the next whole position.
B22: Standard pallet | C22: 1,200 x 1,000 mm footprint, maximum 1,200 mm stack height, maximum 1,000 kg gross. Exceeding any one limit counts as two pallet positions.
B23: Free time | C23: Free time allowances are stated per handling line. Time is counted from vehicle arrival at the gate to release, excluding delays caused by the warehouse.
B24: Invoicing | C24: Storage is invoiced per cycle in advance. Handling and value added services are invoiced in arrears against signed job tickets.
B25: Payment | C25: 30 days net from invoice date, subject to credit approval. New accounts operate on advance payment until credit terms are established.
B26: Late payment | C26: 1.5% per month on balances outstanding beyond agreed terms.
B27: Minimum invoice | C27: A minimum monthly invoice value of SAR 5,000 per account applies.
A29: D. CARGO ACCEPTANCE
B30: Declaration | C30: The client must declare cargo description, HS code, gross weight, dimensions, temperature requirement, hazard classification and declared value in writing before booking.
B31: Dangerous goods | C31: DG cargo is accepted only against a valid MSDS and UN classification, and only into MOI-approved DG areas. Classes 1 (explosives), 6.2 (infectious substances) and 7 (radioactive) are not accepted.
B32: Regulated cargo | C32: Food, pharmaceutical, medical device, cosmetic and animal feed cargo is accepted only where the client holds valid SFDA registration for the product and the facility is licensed for that category.
B33: Right of refusal | C33: The warehouse reserves the right to refuse or quarantine any cargo that is mis-declared, leaking, infested, damaged on arrival, or outside the facility's licensed scope.
B34: Temperature excursion | C34: Cold chain cargo arriving outside its specified range is received under protest into quarantine and is not accepted into sellable stock without written client instruction.
A36: E. LIABILITY & INSURANCE
B37: Basis of liability | C37: Cargo is stored and handled subject to the company's Standard Trading Conditions. Liability attaches only to loss or damage caused by proven negligence of the company or its employees.
B38: Limitation | C38: Liability is limited to SAR 100 per kilogram of the affected cargo, or SAR 50,000 per event, whichever is the lower, unless separate cargo insurance has been purchased through the company.
B39: Exclusions from liability | C39: Inherent vice, latent defect, insufficient or unsuitable packing by the client, ordinary wear, pilferage from sealed units, consequential loss, loss of profit, and force majeure.
B40: Client insurance | C40: Where the client declines cargo insurance, a signed waiver is required and cargo is stored entirely at owner's risk.
B41: Claims | C41: Claims must be notified in writing within 7 days of the event and formally submitted within 30 days. Claims outside these windows are time-barred.
B42: Lien | C42: The company holds a general lien over all cargo in its possession for all sums due, and may sell or dispose of cargo after 90 days' written notice of unpaid balances.
A44: F. TERM & TERMINATION
B45: Minimum term | C45: 12 months from commencement unless otherwise agreed in writing.
B46: Notice | C46: 90 days written notice by either party.
B47: Exit | C47: On termination, all outstanding balances fall due immediately. Stock is released only against cleared payment. Exit transition charges (ITS-007) apply.
...
